Workbook

Sheet feedback elearning
A1: Timestamp | B1: Tên của bạn | C1: Đánh giá trải nghiệm của bạn với khóa Thuyết trình hiệu quả [Trải nghiệm chung] | D1: Đánh giá trải nghiệm của bạn với khóa Thuyết trình hiệu quả [Mức độ hài lòng với nội dung?] | E1: Đánh giá trải nghiệm của bạn với khóa Thuyết trình hiệu quả [Mức độ hài lòng với hình thức khóa E-learning? (VD: nội dung minh họa, tương tác, câu hỏi, bài quiz,...)] | F1: Đánh giá trải nghiệm của bạn với khóa Thuyết trình hiệu quả [Mức độ hài lòng với truyền thông và hỗ trợ của Bộ phận đào tạo?] | G1: Đánh giá trải nghiệm của bạn với khóa No-code Automation [Trải nghiệm chung] | H1: Đánh giá trải nghiệm của bạn với khóa No-code Automation [Mức độ hài lòng với nội dung?] | I1: Đánh giá trải nghiệm của bạn với khóa No-code Automation [Mức độ hài lòng với hình thức khóa E-learning? (VD: nội dung minh họa, tương tác, câu hỏi, bài quiz,...)] | J1: Đánh giá trải nghiệm của bạn với khóa No-code Automation [Mức độ hài lòng với truyền thông và hỗ trợ của Bộ phận đào tạo?] | K1: Đánh giá trải nghiệm của bạn với khóa Sắp xếp ưu tiên và quản trị công việc hiệu quả [Trải nghiệm chung] | L1: Đánh giá trải nghiệm của bạn với khóa Sắp xếp ưu tiên và quản trị công việc hiệu quả [Mức độ hài lòng với nội dung?] | M1: Đánh giá trải nghiệm của bạn với khóa Sắp xếp ưu tiên và quản trị công việc hiệu quả [Mức độ hài lòng với hình thức khóa E-learning? (VD: nội dung minh họa, tương tác, câu hỏi, bài quiz,...)] | N1: Đánh giá trải nghiệm của bạn với khóa Sắp xếp ưu tiên và quản trị công việc hiệu quả [Mức độ hài lòng với truyền thông và hỗ trợ của Bộ phận đào tạo?] | O1: Vui lòng chia sẻ một điều mà bạn học được và có thể áp dụng trong thực tế công việc thông qua các khóa học này? (tùy chọn trả lời) | P1: Vui lòng chia sẻ thêm các phản hồi /gợi ý khác của bạn để cải thiện chất lượng đào tạo? (tùy chọn trả lời)
A2: 46020.738 | B2: Trần Cao Cương | C2: NA - Tôi chưa học khóa này | D2: NA - Tôi chưa học khóa này | E2: NA - Tôi chưa học khóa này | F2: NA - Tôi chưa học khóa này | G2: NA - Tôi chưa học khóa này | H2: NA - Tôi chưa học khóa này | I2: NA - Tôi chưa học khóa này | J2: NA - Tôi chưa học khóa này | K2: 5 | L2: 5 | M2: 5 | N2: 5
A3: 46021.494 | B3: Mai Anh Tuấn | C3: 5 | D3: 5 | E3: 5 | F3: 5 | G3: 5 | H3: 5 | I3: 5 | J3: 5 | K3: 5 | L3: 5 | M3: 5 | N3: 5 | O3: Thuyết trình hiệu quả, trình bày slide hợp lý
A4: 46021.659 | B4: Nhi | C4: 4 | D4: 4 | E4: 4 | F4: 4 | G4: NA - Tôi chưa học khóa này | H4: NA - Tôi chưa học khóa này | I4: NA - Tôi chưa học khóa này | J4: NA - Tôi chưa học khóa này | K4: 4 | L4: 4 | M4: 4 | N4: 4 | O4: Tôi tự xắp xếp thứ tự công việc ưu tiên để không bị chậm dealine | P4: NA
A5: 46021.761 | B5: NGUYEN THI LOAN | C5: 4 | D5: 4 | E5: 4 | F5: 4 | G5: 4 | H5: 4 | I5: 4 | J5: 4 | K5: 4 | L5: 4 | M5: 4 | N5: 4
A6: 46021.778 | B6: Lương Thị Thuý Quỳnh | C6: 5 | D6: 5 | E6: 5 | F6: 5 | G6: 5 | H6: 5 | I6: 5 | J6: 5 | K6: 5 | L6: 5 | M6: 5 | N6: 5
A7: 46022.367 | B7: Trần Thu Trang | C7: 5 | D7: 5 | E7: 5 | F7: 5 | G7: 5 | H7: 5 | I7: 5 | J7: 5 | K7: 5 | L7: 5 | M7: 5 | N7: 5
A8: 46022.384 | B8: Nguyễn Thu Trang | C8: 4 | D8: 4 | E8: 4 | F8: 4 | G8: NA - Tôi chưa học khóa này | H8: NA - Tôi chưa học khóa này | I8: NA - Tôi chưa học khóa này | J8: NA - Tôi chưa học khóa này | K8: 4 | L8: 4 | M8: 4 | N8: 4
A9: 46022.412 | B9: Trần Thu Giang | C9: NA - Tôi chưa học khóa này | D9: NA - Tôi chưa học khóa này | E9: NA - Tôi chưa học khóa này | F9: NA - Tôi chưa học khóa này | G9: 4 | H9: 3 | I9: 3 | J9: 4 | K9: NA - Tôi chưa học khóa này | L9: NA - Tôi chưa học khóa này | M9: NA - Tôi chưa học khóa này | N9: NA - Tôi chưa học khóa này | O9: Biết được một số term để tự tìm hiểu khi làm no-code automation
A10: 46022.414 | B10: The Anh | C10: NA - Tôi chưa học khóa này | D10: NA - Tôi chưa học khóa này | E10: NA - Tôi chưa học khóa này | F10: NA - Tôi chưa học khóa này | G10: 5 | H10: 5 | I10: 5 | J10: 5 | K10: NA - Tôi chưa học khóa này | L10: NA - Tôi chưa học khóa này | M10: NA - Tôi chưa học khóa này | N10: NA - Tôi chưa học khóa này
A11: 46024.428 | B11: Nguyễn Thị Thu Trang | C11: 5 | D11: 5 | E11: 5 | F11: 5 | G11: 5 | H11: 5 | I11: 5 | J11: 5 | K11: 5 | L11: 5 | M11: 5 | N11: 5
A12: 46044.769 | B12: Ngô Thành Trung | C12: 4 | D12: 5 | E12: 5 | F12: 5 | G12: 4 | H12: 4 | I12: 4 | J12: 5 | K12: 5 | L12: 5 | M12: 5 | N12: 5 | O12: Áp dụng trực tiếp vào công việc rất tốt | P12: Khóa nào em cũng hài lòng về nội dung nhưng có khóa em chấm 4 điểm là do còn lỗi chính tả, em nghĩ mình có thể khắc phục ạ
B13: Thân Việt Anh | P13: Hình thức online e thấy hơi thiếu tương tác, kiểu bị 1 chiều bị thiếu phần discussion so với học offline Góp ý thì chắc là ở dạng meeting e nghĩ có thể hiệu quả hơn UI UX thì ok e k gặp vấn đề gì E thấy tương đối ok, cơ mà phần đầu khá nặng lí thuyết Hơi dài, chắc nên thiên về practical case hơn r tự mình ngẫm có fit với công ty k, kiểu học lí thuyết thì hơi giống hồi học ĐH Nếu ở dạng meeting và về mảng muốn học thêm thì e sẵn lòng
B14: Mai Anh Tuấn | P14: Hình thức học tương đối hiệu quả, sinh động, rất thích khi có phần quà được trao Góp ý: Mong muốn có thêm hình thức thực hành, và mong muốn mở rộng thêm các khóa học chuyên sâu về team của mình, ví dụ như em là team product thì em rất muốn nghe các khóa học đến từ các anh bên product, nói về users, revenue, events, ... và các ứng dụng AI thực tế vào công việc của product Nội dung khóa học vô cùng hữu ích Thiết kế bài học hay quiz rất dễ hiểu, site làm tương đối thuận flow khi đọc Rất mong muốn có thêm những bài học tương tự trong tương lại :>
B15: Nguyễn Văn Hoàng | P15: Em thấy học Elearning này khá là hay nhưng mà nó đang chưa giống việc học lắm, hoặc là em thấy nó chưa có impact với em về mảng em muốn học. Các khóa này có thể có ích với người khác thì em chưa rõ. theo cá nhân em đã trải qua 1 khóa elearning em thấy nó chưa thật sự cần thiết với em lắm, khóa đó em học nhằm mục đích tìm hiểu xem như thế nào là chính. ** Mong muốn của em sẽ được mở rộng khóa học với nhiều nội dung hơn ví dụ: khóa học prompt ai, khóa học alpha inteligent hoặc học về alpha knowledge, khóa học về clip.ingarena,toogen ... gì đó sẽ có ích với em hơn. Các khóa học nên có lộ trình dài hơn có thể là vài tháng hoặc vài tuần gì đó. mỗi ngày 2 tiếng hoặc ít hơn. (cái này do em hardcore còn người khác em không rõ :(( ) Nếu có khóa học về lập trình hoặc gì gì đó về kỹ năng hơn sẽ tốt hơn ạ. Em mong muốn có một khóa về tiếng anh bổ túc cho mọi người sẽ hợp lý. Em thấy có nhiều người em làm việc cùng không có tốt về tiếng Anh cho lắm.
B16: Đặng Minh Tuấn | P16: 1/ Mình thấy hình thức này học tiện lợi vì khi rảnh có thể học mọi lúc mà không bị gò bó 2/ Hiện tại thì không có gì khó khăn vì cơ bản đã từng thử nghiệm trên đó 3/ Nội dung khóa rất thực tế, giúp mình tự động hóa được vài task thủ công trong công việc cũng như việc cá nhân 4/ Thiết kế Slide rõ ràng, dễ hiểu. Phần Quiz nên thêm các tình huống "va chạm" :))) 5/ Có muốn học thêm theo hình thức này để có thể biết thêm về nhiều khía cạnh khác các tips để sup cho công việc vì không có thời gian rãnh để học cố định.
B17: Nguyễn Anh Khoa | P17: Nhanh gọn lẹ, hình thức ok nhưng muốn được học chuyên sâu, khó hơn, ra thành quả hơn, các kiến thức này hơi cơ bản xem 1 lần là nhớ và áp dụng được

Sheet Quà Q3
A1: Thủ khoa | B1: minhtri.hoang@garena.vn | C1: 61.5
A3: Row Labels | B3: Sum of Sum of Learning Hours | C3: Column 1 | D3: Quà Learning | E3: Quà Trainer | F3: Column 2 | G3: Hour | H3: Rank | I3: Quà
A4: minhkhoi.nguyen@garena.vn | B4: 75.5 | C4: Gà chăm Cao thủ | F4: {=IFERROR(INDEX(Sheet14!$B$1:$B967,MATCH(A4,Sheet14!$A$1:$A967,0)),"")} -> Gà chăm Cao thủ | G4: 2 | H4: Gà hơi chăm
A5: anhphuong.le@garena.vn | E5: Đế lót ly in hình Gà Learning | F5: {=IFERROR(INDEX(Sheet14!$B$1:$B967,MATCH(A5,Sheet14!$A$1:$A967,0)),"")}
A6: anhtu.nguyen@garena.vn | E6: Đế lót ly in hình Gà Learning | F6: {=IFERROR(INDEX(Sheet14!$B$1:$B967,MATCH(A6,Sheet14!$A$1:$A967,0)),"")}
A7: baoquoc.tongphuoc@garena.vn | E7: Đế lót ly in hình Gà Learning | F7: {=IFERROR(INDEX(Sheet14!$B$1:$B967,MATCH(A7,Sheet14!$A$1:$A967,0)),"")}
A8: quochung.khong@garena.vn | E8: Standee hình Gà | F8: {=IFERROR(INDEX(Sheet14!$B$1:$B967,MATCH(A8,Sheet14!$A$1:$A967,0)),"")} -> Gà chăm Kim cương
F9: {=IFERROR(INDEX(Sheet14!$B$1:$B967,MATCH(A9,Sheet14!$A$1:$A967,0)),"")}
F10: {=IFERROR(INDEX(Sheet14!$B$1:$B967,MATCH(A10,Sheet14!$A$1:$A967,0)),"")}
A11: minhtri.hoang@garena.vn | B11: 75 | C11: Gà chăm Cao thủ | D11: Standee hình Gà, Cốc in hình Gà | E11: Bình giữ nhiệt in hình Gà Learning | F11: {=IFERROR(INDEX(Sheet14!$B$1:$B967,MATCH(A11,Sheet14!$A$1:$A967,0)),"")} -> Gà chăm Kim cương | G11: 5 | H11: Gà chăm Tân thủ | I11: Pin kim loại
A12: hongduc.dao@garena.vn | B12: 72 | C12: Gà chăm Cao thủ | F12: Q1 | G12: 10 | H12: Gà chăm Kim cương | I12: Đế lót ly in hình Gà Learning,
A13: phuongthao.le@garena.vn | B13: 62.5 | C13: Gà chăm Cao thủ | D13: Cốc in hình Gà | F13: {=IFERROR(INDEX(Sheet14!$B$1:$B967,MATCH(A13,Sheet14!$A$1:$A967,0)),"")} | G13: 25 | H13: Gà chăm Tinh Anh | I13: Standee hình Gà,
A14: mylinh.pham@garena.vn | B14: 59.5 | C14: Gà chăm Cao thủ | D14: Pin kim loại, Đế lót ly in hình Gà Learning, Standee hình Gà, Cốc in hình Gà | F14: {=IFERROR(INDEX(Sheet14!$B$1:$B967,MATCH(A14,Sheet14!$A$1:$A967,0)),"")} | G14: 50 | H14: Gà chăm Cao thủ | I14: Cốc in hình Gà,
A15: viethop.nguyen@garena.vn | B15: 46 | C15: Gà chăm Tinh Anh | F15: {=IFERROR(INDEX(Sheet14!$B$1:$B967,MATCH(A15,Sheet14!$A$1:$A967,0)),"")} -> Gà chăm Tinh Anh | G15: =IF(F15=C15,"","Tặng")
A16: lenam.to@garena.vn | B16: 41.5 | C16: Gà chăm Tinh Anh | D16: Standee hình Gà | F16: {=IFERROR(INDEX(Sheet14!$B$1:$B967,MATCH(A16,Sheet14!$A$1:$A967,0)),"")} -> Gà chăm Kim cương | G16: =IF(F16=C16,"","Tặng") -> Tặng
A17: quanghuy.duong@garena.vn | B17: 41 | C17: Gà chăm Tinh Anh | D17: Đế lót ly in hình Gà Learning, Standee hình Gà | F17: {=IFERROR(INDEX(Sheet14!$B$1:$B967,MATCH(A17,Sheet14!$A$1:$A967,0)),"")} -> Gà chăm Tân thủ | G17: =IF(F17=C17,"","Tặng") -> Tặng
A18: tiendat.nguyen@garena.vn | B18: 39.5 | C18: Gà chăm Tinh Anh | D18: Pin kim loại, Đế lót ly in hình Gà Learning, Standee hình Gà | F18: {=IFERROR(INDEX(Sheet14!$B$1:$B967,MATCH(A18,Sheet14!$A$1:$A967,0)),"")} | G18: =IF(F18=C18,"","Tặng") -> Tặng
A19: anhtuan.mai@garena.vn | B19: 39.5 | C19: Gà chăm Tinh Anh | D19: Pin kim loại, Đế lót ly in hình Gà Learning, Standee hình Gà | F19: {=IFERROR(INDEX(Sheet14!$B$1:$B967,MATCH(A19,Sheet14!$A$1:$A967,0)),"")} | G19: =IF(F19=C19,"","Tặng") -> Tặng
A20: traanh.au@garena.vn | B20: 39.5 | C20: Gà chăm Tinh Anh | D20: Standee hình Gà | F20: {=IFERROR(INDEX(Sheet14!$B$1:$B967,MATCH(A20,Sheet14!$A$1:$A967,0)),"")} -> Gà chăm Kim cương | G20: =IF(F20=C20,"","Tặng") -> Tặng
A21: thienkhoa.le@garena.vn | B21: 39 | C21: Gà chăm Tinh Anh | D21: Pin kim loại, Đế lót ly in hình Gà Learning, Standee hình Gà | E21: Cốc in hình Gà | F21: {=IFERROR(INDEX(Sheet14!$B$1:$B967,MATCH(A21,Sheet14!$A$1:$A967,0)),"")} | G21: =IF(F21=C21,"","Tặng") -> Tặng
A22: anhvu.huynh@garena.vn | B22: 35.5 | C22: Gà chăm Tinh Anh | D22: Pin kim loại, Đế lót ly in hình Gà Learning, Standee hình Gà | F22: {=IFERROR(INDEX(Sheet14!$B$1:$B967,MATCH(A22,Sheet14!$A$1:$A967,0)),"")} | G22: =IF(F22=C22,"","Tặng") -> Tặng
A23: duytuan.nguyen@garena.vn | B23: 33.5 | C23: Gà chăm Tinh Anh | D23: Đế lót ly in hình Gà Learning, Standee hình Gà | E23: Pin kim loại, Cốc in hình Gà | F23: {=IFERROR(INDEX(Sheet14!$B$1:$B967,MATCH(A23,Sheet14!$A$1:$A967,0)),"")} -> Gà chăm Tân thủ | G23: =IF(F23=C23,"","Tặng") -> Tặng
A24: vietanh.than@garena.vn | B24: 33.5 | C24: Gà chăm Tinh Anh | D24: Đế lót ly in hình Gà Learning, Standee hình Gà | F24: {=IFERROR(INDEX(Sheet14!$B$1:$B967,MATCH(A24,Sheet14!$A$1:$A967,0)),"")} -> Gà chăm Tân thủ | G24: =IF(F24=C24,"","Tặng") -> Tặng
A25: thuanh.hotran@garena.vn | B25: 33.5 | C25: Gà chăm Tinh Anh | D25: Standee hình Gà | F25: {=IFERROR(INDEX(Sheet14!$B$1:$B967,MATCH(A25,Sheet14!$A$1:$A967,0)),"")} -> Gà chăm Kim cương | G25: =IF(F25=C25,"","Tặng") -> Tặng
A26: thieuky.tran@garena.vn | B26: 33.5 | C26: Gà chăm Tinh Anh | D26: Pin kim loại, Đế lót ly in hình Gà Learning, Standee hình Gà | F26: {=IFERROR(INDEX(Sheet14!$B$1:$B967,MATCH(A26,Sheet14!$A$1:$A967,0)),"")} | G26: =IF(F26=C26,"","Tặng") -> Tặng
A27: thucanh.nguyentran@garena.vn | B27: 33.5 | C27: Gà chăm Tinh Anh | D27: Pin kim loại, Đế lót ly in hình Gà Learning, Standee hình Gà | F27: {=IFERROR(INDEX(Sheet14!$B$1:$B967,MATCH(A27,Sheet14!$A$1:$A967,0)),"")} | G27: =IF(F27=C27,"","Tặng") -> Tặng
A28: ngoctoan.nguyen@garena.vn | B28: 33.5 | C28: Gà chăm Tinh Anh | D28: Pin kim loại, Đế lót ly in hình Gà Learning, Standee hình Gà | F28: {=IFERROR(INDEX(Sheet14!$B$1:$B967,MATCH(A28,Sheet14!$A$1:$A967,0)),"")} | G28: =IF(F28=C28,"","Tặng") -> Tặng
A29: vietanh.pham@garena.vn | B29: 33 | C29: Gà chăm Tinh Anh | D29: Pin kim loại, Đế lót ly in hình Gà Learning, Standee hình Gà | F29: {=IFERROR(INDEX(Sheet14!$B$1:$B967,MATCH(A29,Sheet14!$A$1:$A967,0)),"")} | G29: =IF(F29=C29,"","Tặng") -> Tặng
A30: huyenanh.phan@garena.vn | B30: 31 | C30: Gà chăm Tinh Anh | D30: Standee hình Gà | E30: Cốc in hình Gà, Đế lót ly in hình Gà Learning | F30: {=IFERROR(INDEX(Sheet14!$B$1:$B967,MATCH(A30,Sheet14!$A$1:$A967,0)),"")} -> Gà chăm Kim cương | G30: =IF(F30=C30,"","Tặng") -> Tặng
A31: quochuy.dinh@garena.vn | B31: 30 | C31: Gà chăm Tinh Anh | D31: Pin kim loại, Đế lót ly in hình Gà Learning, Standee hình Gà | F31: {=IFERROR(INDEX(Sheet14!$B$1:$B967,MATCH(A31,Sheet14!$A$1:$A967,0)),"")} | G31: =IF(F31=C31,"","Tặng") -> Tặng
A32: myhanh.luu@garena.vn | B32: 30 | C32: Gà chăm Tinh Anh | D32: Pin kim loại, Đế lót ly in hình Gà Learning, Standee hình Gà | F32: {=IFERROR(INDEX(Sheet14!$B$1:$B967,MATCH(A32,Sheet14!$A$1:$A967,0)),"")} | G32: =IF(F32=C32,"","Tặng") -> Tặng
A33: quangduc.tran@garena.vn | B33: 29.5 | C33: Gà chăm Tinh Anh | D33: Pin kim loại, Đế lót ly in hình Gà Learning, Standee hình Gà | F33: {=IFERROR(INDEX(Sheet14!$B$1:$B967,MATCH(A33,Sheet14!$A$1:$A967,0)),"")} | G33: =IF(F33=C33,"","Tặng") -> Tặng
A34: trang.nguyen@garena.vn | B34: 29.5 | C34: Gà chăm Tinh Anh | D34: Standee hình Gà | F34: {=IFERROR(INDEX(Sheet14!$B$1:$B967,MATCH(A34,Sheet14!$A$1:$A967,0)),"")} -> Gà chăm Kim cương | G34: =IF(F34=C34,"","Tặng") -> Tặng
A35: quangtuan.dao@garena.vn | B35: 29.5 | C35: Gà chăm Tinh Anh | D35: Pin kim loại, Đế lót ly in hình Gà Learning, Standee hình Gà | F35: {=IFERROR(INDEX(Sheet14!$B$1:$B967,MATCH(A35,Sheet14!$A$1:$A967,0)),"")} | G35: =IF(F35=C35,"","Tặng") -> Tặng
A36: theviet.nguyen@garena.vn | B36: 28 | C36: Gà chăm Tinh Anh | D36: Pin kim loại, Đế lót ly in hình Gà Learning, Standee hình Gà | F36: {=IFERROR(INDEX(Sheet14!$B$1:$B967,MATCH(A36,Sheet14!$A$1:$A967,0)),"")} | G36: =IF(F36=C36,"","Tặng") -> Tặng
A37: sygiap.nguyen@garena.vn | B37: 28 | C37: Gà chăm Tinh Anh | D37: Pin kim loại, Đế lót ly in hình Gà Learning, Standee hình Gà | F37: {=IFERROR(INDEX(Sheet14!$B$1:$B967,MATCH(A37,Sheet14!$A$1:$A967,0)),"")} | G37: =IF(F37=C37,"","Tặng") -> Tặng
A38: banhat.nguyen@garena.vn | B38: 27 | C38: Gà chăm Tinh Anh | D38: Pin kim loại, Đế lót ly in hình Gà Learning, Standee hình Gà | E38: Cốc in hình Gà | F38: {=IFERROR(INDEX(Sheet14!$B$1:$B967,MATCH(A38,Sheet14!$A$1:$A967,0)),"")} | G38: =IF(F38=C38,"","Tặng") -> Tặng
A39: minhkhoi.tran@garena.vn | B39: 27 | C39: Gà chăm Tinh Anh | D39: Pin kim loại, Đế lót ly in hình Gà Learning, Standee hình Gà | F39: {=IFERROR(INDEX(Sheet14!$B$1:$B967,MATCH(A39,Sheet14!$A$1:$A967,0)),"")} | G39: =IF(F39=C39,"","Tặng") -> Tặng
A40: huongly.dang@garena.vn | B40: 25.5 | C40: Gà chăm Tinh Anh | D40: Pin kim loại, Đế lót ly in hình Gà Learning, Standee hình Gà | F40: {=IFERROR(INDEX(Sheet14!$B$1:$B967,MATCH(A40,Sheet14!$A$1:$A967,0)),"")} -> Gà chăm Kim cương | G40: =IF(F40=C40,"","Tặng") -> Tặng
A41: anhvu.an@garena.vn | B41: 24.5 | C41: Gà chăm Kim cương | D41: Pin kim loại, Đế lót ly in hình Gà Learning | F41: {=IFERROR(INDEX(Sheet14!$B$1:$B967,MATCH(A41,Sheet14!$A$1:$A967,0)),"")} | G41: =IF(F41=C41,"","Tặng") -> Tặng
...

Sheet Copy of Quà Q3
A1: Thủ khoa | B1: 61.5
A3: Mail | B3: Huy hiệu | C3: Quà tặng 2025 | D3: Quà trainer | E3: Ký nhận | F3: Địa điểm
A4: anhphuong.le@garena.vn | D4: Đế lót ly in hình Gà Learning | F4: Hanoi
A5: anhtu.nguyen@garena.vn | D5: Đế lót ly in hình Gà Learning | F5: Hanoi
A6: baoquoc.tongphuoc@garena.vn | D6: Đế lót ly in hình Gà Learning | F6: Ho Chi Minh
A7: quochung.khong@garena.vn | D7: Standee hình Gà | F7: Hanoi
A8: minhtri.hoang@garena.vn | B8: Gà chăm Cao thủ | C8: Standee hình Gà, Cốc in hình Gà | D8: Bình giữ nhiệt in hình Gà Learning | F8: Hanoi
A9: phuongthao.le@garena.vn | B9: Gà chăm Cao thủ | C9: Cốc in hình Gà | F9: Ho Chi Minh
A10: mylinh.pham@garena.vn | B10: Gà chăm Cao thủ | C10: Pin kim loại, Đế lót ly in hình Gà Learning, Standee hình Gà, Cốc in hình Gà | F10: Hanoi
A11: lenam.to@garena.vn | B11: Gà chăm Tinh Anh | C11: Standee hình Gà | F11: Hanoi
A12: quanghuy.duong@garena.vn | B12: Gà chăm Tinh Anh | C12: Đế lót ly in hình Gà Learning, Standee hình Gà | F12: Hanoi
A13: tiendat.nguyen@garena.vn | B13: Gà chăm Tinh Anh | C13: Pin kim loại, Đế lót ly in hình Gà Learning, Standee hình Gà | F13: Ho Chi Minh
A14: anhtuan.mai@garena.vn | B14: Gà chăm Tinh Anh | C14: Pin kim loại, Đế lót ly in hình Gà Learning, Standee hình Gà | F14: Hanoi
A15: traanh.au@garena.vn | B15: Gà chăm Tinh Anh | C15: Standee hình Gà | F15: Hanoi
A16: thienkhoa.le@garena.vn | B16: Gà chăm Tinh Anh | C16: Pin kim loại, Đế lót ly in hình Gà Learning, Standee hình Gà | D16: Cốc in hình Gà | F16: Ho Chi Minh
A17: anhvu.huynh@garena.vn | B17: Gà chăm Tinh Anh | C17: Pin kim loại, Đế lót ly in hình Gà Learning, Standee hình Gà | F17: Ho Chi Minh
A18: duytuan.nguyen@garena.vn | B18: Gà chăm Tinh Anh | C18: Đế lót ly in hình Gà Learning, Standee hình Gà | D18: Pin kim loại, Cốc in hình Gà | F18: Hanoi
A19: vietanh.than@garena.vn | B19: Gà chăm Tinh Anh | C19: Đế lót ly in hình Gà Learning, Standee hình Gà | F19: Hanoi
A20: thuanh.hotran@garena.vn | B20: Gà chăm Tinh Anh | C20: Standee hình Gà | F20: Hanoi
A21: thieuky.tran@garena.vn | B21: Gà chăm Tinh Anh | C21: Pin kim loại, Đế lót ly in hình Gà Learning, Standee hình Gà | F21: Ho Chi Minh
A22: thucanh.nguyentran@garena.vn | B22: Gà chăm Tinh Anh | C22: Pin kim loại, Đế lót ly in hình Gà Learning, Standee hình Gà | F22: Ho Chi Minh
A23: ngoctoan.nguyen@garena.vn | B23: Gà chăm Tinh Anh | C23: Pin kim loại, Đế lót ly in hình Gà Learning, Standee hình Gà | F23: Hanoi
A24: vietanh.pham@garena.vn | B24: Gà chăm Tinh Anh | C24: Pin kim loại, Đế lót ly in hình Gà Learning, Standee hình Gà | F24: Hanoi
A25: huyenanh.phan@garena.vn | B25: Gà chăm Tinh Anh | C25: Standee hình Gà | D25: Cốc in hình Gà, Đế lót ly in hình Gà Learning | F25: Hanoi
A26: quochuy.dinh@garena.vn | B26: Gà chăm Tinh Anh | C26: Pin kim loại, Đế lót ly in hình Gà Learning, Standee hình Gà | F26: Ho Chi Minh
A27: myhanh.luu@garena.vn | B27: Gà chăm Tinh Anh | C27: Pin kim loại, Đế lót ly in hình Gà Learning, Standee hình Gà | F27: Hanoi
A28: quangduc.tran@garena.vn | B28: Gà chăm Tinh Anh | C28: Pin kim loại, Đế lót ly in hình Gà Learning, Standee hình Gà | F28: Hanoi
A29: trang.nguyen@garena.vn | B29: Gà chăm Tinh Anh | C29: Standee hình Gà | F29: Hanoi
A30: quangtuan.dao@garena.vn | B30: Gà chăm Tinh Anh | C30: Pin kim loại, Đế lót ly in hình Gà Learning, Standee hình Gà | F30: Hanoi
A31: theviet.nguyen@garena.vn | B31: Gà chăm Tinh Anh | C31: Pin kim loại, Đế lót ly in hình Gà Learning, Standee hình Gà | F31: Ho Chi Minh
A32: sygiap.nguyen@garena.vn | B32: Gà chăm Tinh Anh | C32: Pin kim loại, Đế lót ly in hình Gà Learning, Standee hình Gà | F32: Ho Chi Minh
A33: banhat.nguyen@garena.vn | B33: Gà chăm Tinh Anh | C33: Pin kim loại, Đế lót ly in hình Gà Learning, Standee hình Gà | D33: Cốc in hình Gà | F33: Ho Chi Minh
A34: minhkhoi.tran@garena.vn | B34: Gà chăm Tinh Anh | C34: Pin kim loại, Đế lót ly in hình Gà Learning, Standee hình Gà | F34: Ho Chi Minh
A35: anhvu.an@garena.vn | B35: Gà chăm Kim cương | C35: Pin kim loại, Đế lót ly in hình Gà Learning | F35: Ho Chi Minh
A36: quocviet.vuong@garena.vn | B36: Gà chăm Kim cương | C36: Pin kim loại, Đế lót ly in hình Gà Learning | D36: Standee hình Gà | F36: Ho Chi Minh
A37: thanhtung.luu@garena.vn | B37: Gà chăm Kim cương | C37: Pin kim loại, Đế lót ly in hình Gà Learning | F37: Ho Chi Minh
A38: thutrang.pham@garena.vn | B38: Gà chăm Kim cương | C38: Pin kim loại, Đế lót ly in hình Gà Learning | F38: Hanoi
A39: khaitrien.vuu@garena.vn | B39: Gà chăm Kim cương | C39: Pin kim loại, Đế lót ly in hình Gà Learning | F39: Ho Chi Minh
A40: mytram.nguyen@garena.vn | B40: Gà chăm Kim cương | C40: Pin kim loại, Đế lót ly in hình Gà Learning | F40: Ho Chi Minh
A41: anhkhoa.nguyen@garena.vn | B41: Gà chăm Kim cương | C41: Pin kim loại, Đế lót ly in hình Gà Learning | D41: Standee hình Gà | F41: Ho Chi Minh
...

Sheet Sheet14
A1: viethop.nguyen@garena.vn | B1: Gà chăm Tinh Anh
A2: phuongthao.dao@garena.vn | B2: Gà chăm Kim cương
A3: huongly.dang@garena.vn | B3: Gà chăm Kim cương
A4: maiphuong.pham@garena.vn | B4: Gà chăm Kim cương
A5: ducthao.tran@garena.vn | B5: Gà chăm Kim cương
A6: tienduc.nguyen@garena.vn | B6: Gà chăm Kim cương
A7: quoctuan.tran@garena.vn | B7: Gà chăm Kim cương
A8: phuongthao.hoang@garena.vn | B8: Gà chăm Kim cương
A9: lanchi.vu@garena.vn | B9: Gà chăm Kim cương
A10: khaikien.duong@garena.vn | B10: Gà chăm Kim cương
A11: thuanh.hotran@garena.vn | B11: Gà chăm Kim cương
A12: minhtri.hoang@garena.vn | B12: Gà chăm Kim cương
... A53: minhkhoi.nguyen@garena.vn | B53: Gà chăm Cao thủ

Sheet Data Learning Hours chi tiết 20
A1: Mail | B1: Sum of Learning Hours | C1: Course Name | D1: Type | E1: Date Start | F1: Date End
A2: hongduc.dao@garena.vn | B2: 65 | C2: English Online Course (WSE) | D2: Training Budget Sponsor | E2: 45524 | F2: 45708
A3: vananh@garena.vn | B3: 6 | C3: Tax Update 2025 | D3: Training Budget Sponsor | E3: 45706 | F3: 45706
A4: phuonglien.ngo@garena.vn | B4: 6 | C4: Tax Update 2025 | D4: Training Budget Sponsor | E4: 45706 | F4: 45706
A5: thithanh.le@garena.vn | B5: 6 | C5: Tax Update 2025 | D5: Training Budget Sponsor | E5: 45706 | F5: 45706
A6: thutrang.tran@garena.vn | B6: 6 | C6: Tax Update 2025 | D6: Training Budget Sponsor | E6: 45706 | F6: 45706
A7: thutrang.nguyen@garena.vn | B7: 6 | C7: Tax Update 2025 | D7: Training Budget Sponsor | E7: 45706 | F7: 45706
A8: thutrang.nguyenthi@garena.vn | B8: 6 | C8: Tax Update 2025 | D8: Training Budget Sponsor | E8: 45706 | F8: 45706
A9: thuyan.nguyen@garena.vn | B9: 6 | C9: Tax Update 2025 | D9: Training Budget Sponsor | E9: 45706 | F9: 45706
A10: thuyquynh.luong@garena.vn | B10: 5 | C10: Tax Update 2025 | D10: Training Budget Sponsor | E10: 45706 | F10: 45706
A11: thiloan.nguyen@garena.vn | B11: 3 | C11: Tax Update 2025 | D11: Training Budget Sponsor | E11: 45706 | F11: 45706
A12: huyenanh.phan@garena.vn | B12: 12.5 | C12: Marketing Analytics | D12: Training Budget Sponsor | E12: 45663 | F12: 45705
A13: traanh.au@garena.vn | B13: 12.5 | C13: Marketing Analytics | D13: Training Budget Sponsor | E13: 45663 | F13: 45705
A14: lenam.to@garena.vn | B14: 12.5 | C14: Marketing Analytics | D14: Training Budget Sponsor | E14: 45663 | F14: 45705

Sheet Trang tính7
A1: agreement | B1: comments | C1: courseAuthor | D1: courseCertificate | E1: courseDuration | F1: courseEffect | G1: courseEffectByManager | H1: courseEndDate | I1: courseFee | J1: courseFeeByRec | K1: courseFreq | L1: courseName | M1: coursePaymentByRec | N1: courseSMART | O1: courseStartDate | P1: courseTypeByRec | Q1: courseWeb | R1: divider1 | S1: divider2 | T1: email | U1: form_name | V1: id | W1: lastUpdatedAt | X1: po | Y1: raisedAt | Z1: reason | AA1: status | AB1: subsidizeLevel | AC1: subsidizeType | AD1: team
A2: TRUE | C2: DataPot | D2: TRUE | E2: Test | F2: Test | G2: Test | H2: 45099 | I2: 5720000 | J2: 50% chi phí theo khóa học - tương ứng 2.000.000 VNĐ (đã bao gồm 10% VAT) | K2: Test | L2: PowerBI Data Analytics | M2: Khóa học cấp thiết hỗ trợ theo khóa học (tối đa 17tr/khóa; 34tr/năm) | N2: Test | O2: 45095 | P2: X% chi phí theo khóa học - tương ứng X VNĐ (đã bao gồm 10% VAT) | Q2: https://datapot.vn/khoa-hoc/power-bi-advanced-data-modeling-and-dax/ | R2: X | S2: X | T2: minhngoc.phamnguyen@garena.vn | U2: Đăng ký Hỗ trợ chi phí Đào tạo | V2: 36755 | W2: 45421 | X2: minhngoc.phamnguyen@garena.vn | Y2: 45093 | Z2: X | AA2: closed | AB2: Cấp thiết: Trực tiếp nâng cao kỹ năng và kiến thức trong lĩnh vực chuyên môn của nhân viên | AC2: Loại A: Các khóa học cấp chứng chỉ / Hội thảo / Hội nghị / Văn bằng hoặc Bằng cấp (chỉ dành cho học phần) / Nền tảng khóa học trực tuyến mở ví dụ: Udemy | AD2: RECRUITMENT_AND_TRAINING
A3: TRUE | C3: Adobe | I3: 10000000 | J3: ABC | L3: Photoshop 2023 | M3: ABC | P3: ABC | Q3: https://docs.google.com/presentation/d/1UI3grUkAxKz3RrcCHlg0z5Tb2qab2BZ1XzZoukk2wtw/edit#slide=id.g24d0c03fa55_0_2 | R3: Phần 1: Tổng quan nhu cầu của nhân sự | S3: Phần 2: Đề xuất từ bộ phận Đào tạo | T3: minhngoc.phamnguyen@garena.vn | U3: Đăng ký Hỗ trợ chi phí Đào tạo | V3: 36786 | W3: 45143 | X3: minhngoc.phamnguyen@garena.vn | Y3: 45097 | Z3: ABC | AA3: closed | AB3: Cấp thiết: Trực tiếp nâng cao kỹ năng và kiến thức trong lĩnh vực chuyên môn của nhân viên | AC3: Loại B: Tài liệu đọc (Sách điện tử / Sách / Bài báo) | AD3: RECRUITMENT_AND_TRAINING
A4: TRUE | C4: Adobe | D4: TRUE | E4: X | F4: X | G4: X | H4: 45099 | I4: 10000000 | J4: X | K4: X | L4: Photoshop 2023 | M4: X | N4: X | O4: 45097 | P4: X | Q4: https://docs.google.com/presentation/d/1UI3grUkAxKz3RrcCHlg0z5Tb2qab2BZ1XzZoukk2wtw/edit#slide=id.g24d0c03fa55_0_2 | R4: X | S4: X | T4: minhngoc.phamnguyen@garena.vn | U4: Đăng ký Hỗ trợ chi phí Đào tạo | V4: 36788 | W4: 45143 | X4: minhngoc.phamnguyen@garena.vn | Y4: 45097 | Z4: X | AA4: closed | AB4: Cấp thiết: Trực tiếp nâng cao kỹ năng và kiến thức trong lĩnh vực chuyên môn của nhân viên | AC4: Loại A: Các khóa học cấp chứng chỉ / Hội thảo / Hội nghị / Văn bằng hoặc Bằng cấp (chỉ dành cho học phần) / Nền tảng khóa học trực tuyến mở ví dụ: Udemy | AD4: RECRUITMENT_AND_TRAINING
A5: TRUE | C5: DataPot | D5: TRUE | E5: 1h | F5: Test | H5: 45107 | I5: 5720000 | J5: TEst | K5: Test | L5: PowerBI Data Analytics | M5: Test | N5: Test | O5: 45075 | P5: Test | Q5: https://datapot.vn/khoa-hoc/power-bi-advanced-data-modeling-and-dax/ | R5: x | S5: Đề xuất | T5: hoaithuong.tran@garena.vn | U5: Đăng ký Hỗ trợ chi phí Đào tạo | V5: 36793 | W5: 45097 | X5: hoaithuong.tran@garena.vn | Y5: 45097 | Z5: NA | AA5: closed | AB5: Cấp thiết: Trực tiếp nâng cao kỹ năng và kiến thức trong lĩnh vực chuyên môn của nhân viên | AC5: Loại A: Các khóa học cấp chứng chỉ / Hội thảo / Hội nghị / Văn bằng hoặc Bằng cấp (chỉ dành cho học phần) / Nền tảng khóa học trực tuyến mở ví dụ: Udemy | AD5: RECRUITMENT_AND_TRAINING
A6: TRUE | B6: Em gửi thông báo kết quả phê duyệt + hướng dẫn đăng ký mua & claim chi phí mua tài liệu nhé ạ: https://drive.google.com/file/d/1btSKE-2nWabJ0IRbUIxCXSdamwiXbe6e/view?usp=drive_link | J6: 100% chi phí của tài liệu - tương ứng 3.500.000 VNĐ | M6: Nhân viên tự trả tiền trước và claim theo mã dự án training | P6: Hạng mục cấp thiết hỗ trợ theo tài liệu (tối đa 17tr/khóa hoặc tài liệu; tối đa 34tr/năm) | R6: Chi tiết nhu cầu của nhân sự đề xuất | S6: Chi tiết đề xuất từ bộ phận Đào tạo (dựa trên chính sách Hỗ trợ chi phí Đào tạo của Công ty) | T6: vananh.le@garena.vn | U6: Đăng ký Hỗ trợ chi phí Đào tạo | V6: 36813 | W6: 45152 | X6: vananh.le@garena.vn | Y6: 45097 | Z6: BP Đào tạo đề xuất | AA6: closed | AB6: Cấp thiết: Trực tiếp nâng cao kỹ năng và kiến thức trong lĩnh vực chuyên môn của nhân viên | AC6: Loại B: Tài liệu đọc (Sách điện tử / Sách / Bài báo) | AD6: HRBP
A7: TRUE | B7: Account học online, team C&B sử dụng chung | C7: VCCI | D7: TRUE | E7: 2 ngày | F7: Update chính sách quy định của BLLĐ đảm bảo tính compliance các chính sách/hồ sơ liên quan đến lao động của Công ty. Giảm thiểu tối đa các sai sót khi có thanh tra. | H7: 45157 | I7: 1000000 VND | J7: 100% chi phí của tài liệu - tương ứng 1.000.000 VND | L7: CHÍNH SÁCH LAO ĐỘNG TIỀN LƯƠNG và BẢO HIỂM XÃ HỘI 2023 | M7: Nhân viên tự trả tiền trước và claim theo mã dự án training | N7: S: củng cố/cập nhật các quy định mới liên quan đến tính compliance của các chính sách nhân sự M: không có chính sách/quy định nào trái luật A: đảm bảo hệ thống chính sách/văn bản nhân sự đúng đủ R: liên quan đến các chính sách nhân sự khi hướng dẫn nhân viên/thanh kiểm tra T: đánh giá qua các kỳ rà soát chính sách quy định nhân sự | O7: 45156 | P7: Hạng mục cấp thiết hỗ trợ theo khóa (tối đa 17tr/khóa; tối đa 34tr/năm) | Q7: https://edu.vcciesp.vn/chinh.sach.lao.dong.2023?fbclid=IwAR0HunO6XFHW1F_JhHwNQEOoVUKkv1UKCF5BZPHlCqNmZHQetbQuf0DvU0g | R7: Chi tiết nhu cầu của nhân sự đề xuất | S7: Chi tiết đề xuất từ bộ phận Đào tạo (dựa trên chính sách Hỗ trợ chi phí Đào tạo của Công ty) | T7: myhanh.luu@garena.vn | U7: Đăng ký Hỗ trợ chi phí Đào tạo | V7: 37761 | W7: 45147 | X7: myhanh.luu@garena.vn | Y7: 45146 | Z7: BP Đào tạo đề xuất | AA7: closed | AB7: Cấp thiết: Trực tiếp nâng cao kỹ năng và kiến thức trong lĩnh vực chuyên môn của nhân viên | AC7: Loại A: Các khóa học cấp chứng chỉ / Hội thảo / Hội nghị / Văn bằng hoặc Bằng cấp (chỉ dành cho học phần) / Nền tảng khóa học trực tuyến mở ví dụ: Udemy | AD7: CNB
A8: TRUE | B8: Em gửi thông báo kết quả phê duyệt + hướng dẫn đăng ký mua & claim chi phí mua tài liệu nhé ạ: https://drive.google.com/file/d/15NrLZit4G19CexyGuyhzj90UUaACs6Wc/view?usp=sharing | C8: VCCI | D8: TRUE | E8: 2 ngày | F8: Update chính sách quy định của BLLĐ đảm bảo tính compliance các chính sách/hồ sơ liên quan đến lao động của Công ty. Giảm thiểu tối đa các sai sót khi có thanh tra. | H8: 45157 | I8: 1000000 vnd | J8: 100% chi phí của tài liệu - tương ứng 1.000.000 VND | L8: CHÍNH SÁCH LAO ĐỘNG TIỀN LƯƠNG và BẢO HIỂM XÃ HỘI 2023 | M8: Nhân viên tự trả tiền trước và claim theo mã dự án training | N8: S: củng cố/cập nhật các quy định mới liên quan đến tính compliance của các chính sách nhân sự M: không có chính sách/quy định nào trái luật A: đảm bảo hệ thống chính sách/văn bản nhân sự đúng đủ R: liên quan đến các chính sách nhân sự khi hướng dẫn nhân viên/thanh kiểm tra T: đánh giá qua các kỳ rà soát chính sách quy định nhân sự | O8: 45156 | P8: Hạng mục cấp thiết hỗ trợ theo khóa (tối đa 17tr/khóa; tối đa 34tr/năm) | Q8: https://edu.vcciesp.vn/chinh.sach.lao.dong.2023?fbclid=IwAR0HunO6XFHW1F_JhHwNQEOoVUKkv1UKCF5BZPHlCqNmZHQetbQuf0DvU0g | R8: Chi tiết nhu cầu của nhân sự đề xuất | S8: Chi tiết đề xuất từ bộ phận Đào tạo (dựa trên chính sách Hỗ trợ chi phí Đào tạo của Công ty) | T8: myhanh.luu@garena.vn | U8: Đăng ký Hỗ trợ chi phí Đào tạo | V8: 37771 | W8: 45194 | X8: myhanh.luu@garena.vn | Y8: 45147 | Z8: BP Đào tạo đề xuất | AA8: closed | AB8: Cấp thiết: Trực tiếp nâng cao kỹ năng và kiến thức trong lĩnh vực chuyên môn của nhân viên | AC8: Loại A: Các khóa học cấp chứng chỉ / Hội thảo / Hội nghị / Văn bằng hoặc Bằng cấp (chỉ dành cho học phần) / Nền tảng khóa học trực tuyến mở ví dụ: Udemy | AD8: CNB
A9: TRUE | B9: Em gửi thông báo kết quả phê duyệt + hướng dẫn đăng ký khóa học & claim chi phí nhé ạ: https://drive.google.com/file/d/1-v4xdO3ZwLAcKDR6lKMDvK7nCvE5kX6o/view?usp=sharing | C9: DataPot | D9: TRUE | E9: 16 buổi - 32 giờ học | F9: Khóa học giúp đạt được các kỹ năng: - Nhập làm sạch và chuyển đổi dữ liệu - Mô hình hóa dữ liệu cho hiệu suất và khả năng mở rộng - Thiết kế và tạo báo cáo để phân tích dữ liệu - Áp dụng và thực hiện phân tích báo cáo nâng cao - Quản lý và chia sẻ nội dung báo cáo - Tạo báo cáo được phân trang trong Power BI Các kỹ năng trên bổ trợ trực tiếp cho công việc phân tích dữ liệu nhằm phát triển công ty. | H9: 45226 | I9: 6.048.000 VNĐ (bao gồm 8% VAT - cập nhật theo báo giá mới nhất của Datapot) | J9: 100% chi phí của khóa học - tương ứng 6.048.000 VNĐ | K9: 2 buổi 1 tuần | L9: ANALYZING DATA WITH POWER BI (Fresher) | M9: Nhân viên tự trả tiền trước và claim theo mã dự án training | N9: - S: Bổ sung kiến thức phân tích dữ liệu bằng công cụ Power BI để phục vụ công việc tracking data - M: Đạt mục tiêu xử lý dữ liệu sạch có ý nghĩa để đưa ra quyết định next step phù hợp với team - A: Bắt tay vào cùng phân tích dữ liệu với anh Hải Sơn càng sớm càng tốt - R: Xử lý dữ liệu để đưa ra quyết định phù hợp với định hướng của con game và công ty - T: Hoàn thành khóa học trong 2 tháng ứng dụng luôn vào công việc => Có khả năng phân tích dữ liệu từ tháng 11 (hoặc sớm hơn). | O9: 45174 | P9: Hạng mục cấp thiết hỗ trợ theo tài liệu (tối đa 17tr/khóa; tối đa 34tr/năm) | Q9: https://datapot.vn/khoa-hoc/da-100-analyzing-data-with-power-bi/ | R9: Chi tiết nhu cầu của nhân sự đề xuất | S9: Chi tiết đề xuất từ bộ phận Đào tạo (dựa trên chính sách Hỗ trợ chi phí Đào tạo của Công ty) | T9: huyenanh.phan@garena.vn | U9: Đăng ký Hỗ trợ chi phí Đào tạo | V9: 37945 | W9: 45244 | X9: huyenanh.phan@garena.vn | Y9: 45156 | Z9: BP Đào tạo đề xuất | AA9: approving | AB9: Cấp thiết: Trực tiếp nâng cao kỹ năng và kiến thức trong lĩnh vực chuyên môn của nhân viên | AC9: Loại A: Các khóa học cấp chứng chỉ / Hội thảo / Hội nghị / Văn bằng hoặc Bằng cấp (chỉ dành cho học phần) / Nền tảng khóa học trực tuyến mở ví dụ: Udemy | AD9: AOV
A10: TRUE | C10: Project Management Institute | D10: TRUE | E10: N/A | F10: Hiện tại để tăng cường tối ưu hiệu quả hoạt động vận hành giảm bớt nhân sự làm các công việc thủ công như trước kia nên nhu cầu gia tăng nhiều dự án phát triển phần mềm dài hạn có tính chất phức tạp đòi hỏi yêu cầu quản lý dự án ở mức nâng cao và chuyên nghiệp hơn. Do đó cần học thêm khoá học này để áp dụng các mô hình quản lý dự án chuyên nghiệp học thêm nhiều technique để rút ngắn thời gian nâng cao hiệu suất giúp có thể đồng thời xử lý được nhiều dự án với chất lượng tốt hơn phục vụ tốt hơn cho nhu cầu của các team game và công ty. Ngoài ra khoá học cũng cũng cấp nhiều use case để có thể vận dụng trong nhiều tình huống thực tế tăng khả năng hài lòng của các thành viên tham gia dự án. | H10: 45473 | I10: 555 | J10: 100% chi phí của chứng chỉ - tương ứng $555 ~ 13 436 550 (tỉ giá: 1 USD = 24 210 VNĐ) - chưa tính các thuế phí liên quan đến thanh toán ra nước ngoài & có thể điều chỉnh về tỉ giá tại thời điểm thanh toán | L10: Project Management Professional (PMP)® | M10: Nhân viên tự trả tiền trước và claim theo mã dự án training | N10: - S: Tôi sẽ tăng cường các kỹ năng quản lý dự án hiệu quả hơn - M: Tôi sẽ đặt mục tiêu nâng cao kỹ năng trên tất cả các phương diện như con người quá trình và hiệu quả kinh doanh - R: Tăng cường hiệu quả trong việc quản lý dự án chuyên nghiệp - T: Tôi sẽ đạt được điều này trong sáu tháng tới => Tôi sẽ hoàn thành chứng chỉ vào tháng 6 năm 2024 | O10: 45281 | P10: Hạng mục cấp thiết hỗ trợ theo tài liệu (tối đa 17tr/khóa; tối đa 34tr/năm) | Q10: https://www.pmi.org/certifications/project-management-pmp | R10: Chi tiết nhu cầu của nhân sự đề xuất | S10: Chi tiết đề xuất từ bộ phận Đào tạo (dựa trên chính sách Hỗ trợ chi phí Đào tạo của Công ty) | T10: dinhphuc.luu@garena.vn | U10: Đăng ký Hỗ trợ chi phí Đào tạo | V10: 40200 | W10: 45499 | X10: dinhphuc.luu@garena.vn | Y10: 45281 | Z10: BP Đào tạo đề xuất | AA10: closed | AB10: Cấp thiết: Trực tiếp nâng cao kỹ năng và kiến thức trong lĩnh vực chuyên môn của nhân viên | AC10: Loại A: Các khóa học cấp chứng chỉ / Hội thảo / Hội nghị / Văn bằng hoặc Bằng cấp (chỉ dành cho học phần) / Nền tảng khóa học trực tuyến mở ví dụ: Udemy | AD10: CODE
A11: TRUE | B11: Em gửi thông báo kết quả phê duyệt + hướng dẫn đăng ký khóa học & claim chi phí nhé ạ: https://drive.google.com/file/d/1wY6zNRr4ixYm7Nd_ecchXqP5f0nveO7T/view?usp=sharing | C11: Công ty TNHH Phát Triển aroma - Aroma Tiếng Anh cho người đi làm | D11: TRUE | E11: 40 giờ | F11: 1. Đặc thù vị trí công việc làm việc với các khu vực khác đối tác nước ngoài. Nâng cao trình độ tiếng anh để nâng cao khả năng giao tiếp trao đổi trong tất cả các dự án. | H11: 45442 | I11: 16.380.000 VNĐ | J11: 50% chi phí của chứng chỉ - tương ứng 8.190.000 VNĐ | K11: 2-3 buổi/tuần | L11: Khóa học tiếng anh Intermediate level | M11: Nhân viên tự trả tiền trước và claim theo mã dự án training | N11: - S: Tăng cường kỹ năng giao tiếp khi làm việc với local team hay đối tác nước ngoài. - M: Sau khóa học ngắn hạn có thể xác định được trình độ đặt mục tiêu cải thiện ở mực độ cao hơn và có target rõ ràng bằng chứng chỉ IELTS. - A: Xác định trình độ mục tiêu cho chứng chỉ IELTS. - R: Tối ưu giao tiếp trong giải đoạn chuẩn bị giải đấu APL 2024 tại Thái Lan. - T: Đạt được điều này trong 6 tháng tới khóa học này là bước đầu để cải thiện lại nền tảng ngữ pháp. => Nâng cao kỹ năng giao tiếp khi làm việc bằng tiếng anh giảm thiểu thời gian khi chuẩn bị các tài liệu bằng tiếng anh (report review sop...etc) | O11: 45300 | P11: Hạng mục bổ trợ - tối đa 8.5 triệu VND/ nội dung | Q11: http://aroma.vn/tieng-anh-cho-nguoi-di-lam/ | R11: Chi tiết nhu cầu của nhân sự đề xuất | S11: Chi tiết đề xuất từ bộ phận Đào tạo (dựa trên chính sách Hỗ trợ chi phí Đào tạo của Công ty) | T11: hongduc.le@garena.vn | U11: Đăng ký Hỗ trợ chi phí Đào tạo | V11: 40434 | W11: 45306 | X11: hongduc.le@garena.vn | Y11: 45295 | Z11: BP Đào tạo đề xuất | AA11: processing | AB11: Bổ trợ: Bổ trợ cho các kỹ năng và kiến thức trong lĩnh vực chuyên môn của nhân viên | AC11: Loại A: Các khóa học cấp chứng chỉ / Hội thảo / Hội nghị / Văn bằng hoặc Bằng cấp (chỉ dành cho học phần) / Nền tảng khóa học trực tuyến mở ví dụ: Udemy | AD11: AOV
A12: TRUE | C12: Học viện Công nghệ Bưu Chính Viễn Thông | D12: TRUE | E12: 4 5 năm | F12: Trong quản lý dự án kiến thức Khoa học Máy tính sẽ giúp tôi rất nhiều như quá trình lập kế hoạch đánh giá hiệu quả lựa chọn giải pháp phù hợp. Điều này sẽ tăng cường khả năng ra quyết định thông minh tối ưu hóa quá trình quản lý và mang lại hiệu suất cao cho dự án. Đặc biệt với sự xuất hiện nhiều dự án mới đòi hỏi nhiều kiến thức chuyên sâu về khoa học máy tính như dự án về AI Blockchain kiến thức vững về Khoa học Máy tính mang lại nền tảng vững chắc cho công việc hiệu quả hơn. Ngoài ra sự hiểu biết vững về Khoa học Máy tính giúp tôi làm việc hiệu quả hơn với đội ngũ dự án cả local và region dễ dàng trao đồi bàn bạc và đưa ra đánh giá và ước tính chính xác hơn cũng như đề xuất những giải pháp sáng tạo. Từ đó tôi có thể quản lý nhiều dự án công nghệ phức tạp nhanh chóng và hiệu quả hơn góp phần hỗ trợ công ty giải quyết nhiều vấn đề về business tiết kiệm chi phí vận hành và tối đa hoá doanh thu. | H12: 46600 | I12: 62000000 | L12: Kỹ sư Khoa học máy tính | N12: - S: Tôi sẽ nâng cao kiến thức chuyên môn về các phương pháp phát triển phần mềm nâng cao khả năng quản lý các dự án phần mềm một cách hiệu quả. - M: Tôi sẽ đặt mục tiêu nâng cao kỹ năng trên tất cả các phương diện như kiến thức kỹ năng giải quyết vấn đề nắm bắt nền tảng công nghệ mới - R: cung cấp sự hiểu biết kỹ thuật sâu sắc hơn cho phép tôi đóng góp một cách chiến lược hơn cho các dự án phù hợp với mục tiêu dài hạn của công ty - T: Tôi sẽ đạt được điều này trong ba năm tới => Tôi sẽ hoàn thành vào năm 2027 | O12: 45047 | Q12: https://daotao.ptit.edu.vn/nganhhoc/7480101 | T12: dinhphuc.luu@garena.vn | U12: Đăng ký Hỗ trợ chi phí Đào tạo | V12: 40825 | W12: 45309 | X12: dinhphuc.luu@garena.vn | Y12: 45308 | Z12: Update | AA12: closed | AB12: Cấp thiết: Trực tiếp nâng cao kỹ năng và kiến thức trong lĩnh vực chuyên môn của nhân viên | AC12: Loại A: Các khóa học cấp chứng chỉ / Hội thảo / Hội nghị / Văn bằng hoặc Bằng cấp (chỉ dành cho học phần) / Nền tảng khóa học trực tuyến mở ví dụ: Udemy | AD12: CODE
A13: TRUE | B13: Em gửi thông báo kết quả phê duyệt + hướng dẫn đăng ký khóa học & claim chi phí nhé ạ: https://drive.google.com/file/d/1dWty4xDaatC5xcbKbL5lMRyDRQumfo9y/view?usp=drive_link | C13: DataPot | D13: TRUE | E13: 16 buổi | F13: Xử lý data cho team AOV Esports Regional và 3 Local teams: VN/TH/TW. Từ đó đưa ra phân tích dữ liệu và kế hoạch marketing tốt hơn cho team Esports. | H13: 45435 | I13: 6.264.000 VNĐ (đã bao gồm VAT) | J13: 100% chi phí của khóa học - tương ứng 6.264.000 VNĐ | K13: 2 buổi/tuần | L13: PowerBI Data Analytics | M13: Nhân viên tự trả tiền trước và claim theo mã dự án training | N13: - S: Bổ sung kiến thức nâng cao phân tích dữ liệu bằng công cụ Power BI để phục vụ công việc tracking data - M: Đạt mục tiêu xử lý dữ liệu sạch có ý nghĩa để đưa ra quyết định next step phù hợp với team - A: Đưa ra phân tích & định hướng tốt hơn cho AOV Esports Regional Team và 2 Locals team còn lại: TH/TW - R: Xử lý dữ liệu để đưa ra quyết định phù hợp với định hướng của con game và công ty - T: Hoàn thành khóa học trong 2 tháng ứng dụng nâng cao được vào công việc=> Có khả năng Xử lý data nâng cao cho team AOV Esports Regional và 3 Local teams: VN/TH/TW | O13: 45379 | P13: Hạng mục cấp thiết - tối đa 17 triệu VND/ khóa/năm | Q13: https://datapot.vn/khoa-hoc/da-100-analyzing-data-with-power-bi/ | R13: Chi tiết nhu cầu của nhân sự đề xuất | S13: Chi tiết đề xuất từ bộ phận Đào tạo (dựa trên chính sách Hỗ trợ chi phí Đào tạo của Công ty) | T13: quochung.khong@garena.vn | U13: Đăng ký Hỗ trợ chi phí Đào tạo | V13: 41536 | W13: 45364 | X13: quochung.khong@garena.vn | Y13: 45357 | Z13: BP Đào tạo đề xuất | AA13: processing | AB13: Cấp thiết: Trực tiếp nâng cao kỹ năng và kiến thức trong lĩnh vực chuyên môn của nhân viên | AC13: Loại A: Các khóa học cấp chứng chỉ / Hội thảo / Hội nghị / Văn bằng hoặc Bằng cấp (chỉ dành cho học phần) / Nền tảng khóa học trực tuyến mở ví dụ: Udemy | AD13: AOV
A14: TRUE | B14: #ERROR! | C14: Udemy | D14: TRUE | E14: 10 hours | F14: Hiện tại vấn đề cải thiện trải nghiệm của người dùng chưa được chú trọng do đó cần cập nhật kiến thức và sharing đến các PO desingers để cùng phối hợp đưa ra sản phẩm mang tới trải nghiệm tốt hơn cho người dùng đặc biệt trên phiên bản mobile. | H14: 45373 | I14: 2199000 | L14: User Experience Design Fundamentals | N14: - S: Ôn tập và phát triển kiến thức cho buổi sharing sắp tới - M: Tôi sẽ đặt mục tiêu nâng cao kiến thức đồng thời phổ biến kiến thức cho các team khác - R: Tăng cường hiệu quả trong việc cải thiện trải nghiệm người dùng trên mobile - T: Tôi sẽ đạt được điều này trong một tháng tới => Tôi sẽ dự kiến có buổi sharing vào tháng 4 | O14: 45373 | Q14: https://www.udemy.com/course/user-experience-design-fundamentals/ | T14: dinhphuc.luu@garena.vn | U14: Đăng ký Hỗ trợ chi phí Đào tạo | V14: 41877 | W14: 45387 | X14: dinhphuc.luu@garena.vn | Y14: 45373 | AA14: closed | AB14: Cấp thiết: Trực tiếp nâng cao kỹ năng và kiến thức trong lĩnh vực chuyên môn của nhân viên | AC14: Loại A: Các khóa học cấp chứng chỉ / Hội thảo / Hội nghị / Văn bằng hoặc Bằng cấp (chỉ dành cho học phần) / Nền tảng khóa học trực tuyến mở ví dụ: Udemy | AD14: CODE
A15: TRUE | B15: Em gửi thông báo kết quả phê duyệt + hướng dẫn đăng ký khóa học & claim chi phí nhé ạ: https://drive.google.com/file/d/1yHL7KDjuiMr3p7JbthSXRnzCQ-Ah5hL2/view?usp=drive_link | C15: Coursera | D15: TRUE | E15: 1 month | F15: Python giúp phân tích dữ liệu tạo trực quan hóa dữ liệu giúp phân tích dữ liệu hiệu quả hơn => Hỗ trợ tốt trong việc thống kê dữ lliệu và sự so sánh dữ liệu giữa các campaign tốt hơn giúp việc planning cho các campaign sau hiệu quả hơn | H15: 45395 | I15: 49$ | J15: 50% của khóa học - tương ứng 673.241 VNĐ (đã bao gồm 5% VAT và 5% CIT) | K15: 3 days per week | L15: Python Basic | M15: Nhân viên tự trả tiền trước và claim theo mã dự án training | N15: S: Tìm hiểu Python để hỗ trợ tôi trong việc phát triển các data tool phục vụ hiệu quả trobg quá trình làm việc dễ dàng hơn trong việc trao đổi với code team. M: Giảm 20 - 30% thời gian planning manage scope công việc và check data trong quá trình vận hành campaign. A: Tôi đặt mục tiêu tạo ra 1 hệ thống thống kê data và kiểm soát scope công việc + planning dễ follow up hơn. R: Kiểm soát scope tốt đẻ tăng hiệu quả công việc giảm bớt thời gian execute T: Dự kiến có logic rõ ràng trong 1 tháng sau khi hoàn thành khóa học sau đó sẽ tiến hành các bước tiếp theo với các team liên quan | O15: 45364 | P15: Hạng mục bổ trợ - tối đa 8.5 triệu VND / nội dung | Q15: https://www.coursera.org/learn/python | R15: Chi tiết nhu cầu của nhân sự đề xuất | S15: Chi tiết đề xuất từ bộ phận Đào tạo (dựa trên chính sách Hỗ trợ chi phí Đào tạo của Công ty) | T15: phuonglinh.pham@garena.vn | U15: Đăng ký Hỗ trợ chi phí Đào tạo | V15: 42062 | W15: 45397 | X15: phuonglinh.pham@garena.vn | Y15: 45387 | Z15: BP Đào tạo đề xuất | AA15: processing | AB15: Bổ trợ: Bổ trợ cho các kỹ năng và kiến thức trong lĩnh vực chuyên môn của nhân viên | AC15: Loại A: Các khóa học cấp chứng chỉ / Hội thảo / Hội nghị / Văn bằng hoặc Bằng cấp (chỉ dành cho học phần) / Nền tảng khóa học trực tuyến mở ví dụ: Udemy | AD15: FC Online
A16: TRUE | B16: Em gửi thông báo kết quả phê duyệt + hướng dẫn đăng ký khóa học & claim chi phí nhé ạ: https://drive.google.com/file/d/1H9sgA00u5V181zTB8-MgzeN-0X4CRal1/view?usp=drive_link | C16: ELITE PR SCHOOL | D16: TRUE | E16: 6 buổi | F16: Đạt được các mục tiêu theo goal setting committed | H16: 45409 | I16: 6.000.000 VNĐ (chưa VAT) | J16: 100% của khóa học - tương ứng 6.000.000 VNĐ (chưa VAT) | L16: Xây dựng văn hóa doanh nghiệp và hệ thống truyền thông nội bộ | M16: Nhân viên tự trả tiền trước và claim theo mã dự án training | N16: - S: Thiết kế các hoạt động TTNB thiết thực thu hút và tăng engagement rate trong năm 2024 (~90%) - M: Xây dựng được tiêu chí phương thức đo lường và đánh giá hiệu quả các hoạt động TTNB - A: Biết cách khảo sát phân tích đặc trưng văn hoá từ đó xây dựng được nền móng và các trụ cột văn hoá doanh nghiệp. Nắm được cấu trúc hệ thống quy trình hoạch định kế hoạch truyền thông nội bộ hợp lý. - R: Cải thiện được các hoạt động nội bộ sẽ dẫn đến sự gắn kết giữa các nhân viên và công ty. Ngoài ra đồng bộ thông tin truyền thông nội bộ cho thấy được sự chuyên nghiệp và nhất quán từ công ty -> tiền đề để xây dựng văn hoa riêng.- T: Cải thiện được đo lường từ số lượng và chất lượng theo từng quý/ từng sự kiện và dự án truyền thông | O16: 45402 | P16: Hạng mục cấp thiết - tối đa 17 triệu VND / nội dung | Q16: https://eliteprschool.edu.vn/van-hoa-doanh-nghiep-ttnb/ | R16: Chi tiết nhu cầu của nhân sự đề xuất | S16: Chi tiết đề xuất từ bộ phận Đào tạo (dựa trên chính sách Hỗ trợ chi phí Đào tạo của Công ty) | T16: linhtrang.tran@garena.vn | U16: Đăng ký Hỗ trợ chi phí Đào tạo | V16: 42110 | W16: 45397 | X16: linhtrang.tran@garena.vn | Y16: 45391 | Z16: Bổ sung thêm về mục tiêu học tập | AA16: processing | AB16: Cấp thiết: Trực tiếp nâng cao kỹ năng và kiến thức trong lĩnh vực chuyên môn của nhân viên | AC16: Loại A: Các khóa học cấp chứng chỉ / Hội thảo / Hội nghị / Văn bằng hoặc Bằng cấp (chỉ dành cho học phần) / Nền tảng khóa học trực tuyến mở ví dụ: Udemy | AD16: PEOPLE
A17: TRUE | B17: Em gửi thông báo kết quả phê duyệt + hướng dẫn đăng ký khóa học & claim chi phí nhé ạ: https://drive.google.com/file/d/1W-oXtcal3X3F_9Y3vswRaUOBNsoPKULw/view?usp=sharing | C17: Tomorrow marketers | D17: TRUE | E17: 12 buổi | F17: Cải thiện hệ thống tracking dữ liệu kết quả với KPI cho các hoạt động MKT của team. Training lại cho các thành viên trong team quy trình và mindset phân tích dữ liệu khi đưa ra quyết định trong các hoạt động MKT | H17: 45477 | I17: 5.750.000 VND | J17: 100% của khóa học - tương ứng 5.750.000 VNĐ (VAT 0%) | K17: 2 buổi/tuần | L17: Phân tích dữ liệu cho quyết định chiến lược | N17: S: Cải thiện hệ thống tracking dữ liệu kết quả với KPI cho các hoạt động MKT của team M: Đặt mục tiêu thu hút tổng new user và churn user back của FCO trong quý 2 đạt 1.2M A: Training lại cho các thành viên trong team quy trình và mindset phân tích dữ liệu khi đưa ra quyết định trong các hoạt động MKT R: Tăng trưởng người dùng cho thấy sự phát triển của tựa game T: Đạt được điều này trong 2 tháng tới sau đó đánh giá lại trước khi lập kế hoạch cho các bước tiếp theo | O17: 45435 | Q17: https://www.tomorrowmarketers.org/data-analysis-course | R17: Chi tiết nhu cầu của nhân sự đề xuất | S17: Chi tiết đề xuất từ bộ phận Đào tạo (dựa trên chính sách Hỗ trợ chi phí Đào tạo của Công ty) | T17: phuongthao.le@garena.vn | U17: Đăng ký Hỗ trợ chi phí Đào tạo | V17: 42269 | W17: 45516 | X17: phuongthao.le@garena.vn | Y17: 45401 | Z17: BP Đào tạo cập nhật đề xuất | AA17: processing | AB17: Cấp thiết: Trực tiếp nâng cao kỹ năng và kiến thức trong lĩnh vực chuyên môn của nhân viên | AC17: Loại A: Các khóa học cấp chứng chỉ / Hội thảo / Hội nghị / Văn bằng hoặc Bằng cấp (chỉ dành cho học phần) / Nền tảng khóa học trực tuyến mở ví dụ: Udemy | AD17: FC Online
A18: TRUE | B18: Em gửi hướng dẫn thanh toán và đăng ký, tham gia khóa học nhé ạ: https://drive.google.com/file/d/1NT6B4a9kn5QEY5wv14oA12rab6RIJ-bG/view?usp=sharing | C18: Datapot | D18: TRUE | E18: 16 buổi - 32 giờ | F18: Tăng hiệu suất làm việc tự chủ động quản lý và tìm ra những giải pháp tối ưu hơn cho dự án dựa trên số liệu | H18: 45510 | I18: 6000000 | J18: 100% của khóa học - tương ứng 6.480.000 VNĐ (bao gồm VAT 8%) | L18: PowerBI Data Analytics Basic | M18: Nhân viên tự trả tiền trước và claim theo mã dự án training | N18: Học lý thuyết bài bản về công cụ Power BI để sử dụng từ cơ bản tới nâng cao | O18: 45457 | P18: Hạng mục cấp thiết - tối đa 17 triệu VND / nội dung | Q18: https://datapot.vn/khoa-hoc/da-100-analyzing-data-with-power-bi/ | R18: Chi tiết nhu cầu của nhân sự đề xuất | S18: Chi tiết đề xuất từ bộ phận Đào tạo (dựa trên chính sách Hỗ trợ chi phí Đào tạo của Công ty) | T18: quanghuy.duong@garena.vn | U18: Đăng ký Hỗ trợ chi phí Đào tạo | V18: 42539 | W18: 45531 | X18: quanghuy.duong@garena.vn | Y18: 45420 | Z18: BP Đào tạo đề xuất | AA18: closed | AB18: Cấp thiết: Trực tiếp nâng cao kỹ năng và kiến thức trong lĩnh vực chuyên môn của nhân viên | AC18: Loại A: Các khóa học cấp chứng chỉ / Hội thảo / Hội nghị / Văn bằng hoặc Bằng cấp (chỉ dành cho học phần) / Nền tảng khóa học trực tuyến mở ví dụ: Udemy | AD18: 3KD
A19: TRUE | C19: W3School | D19: TRUE | E19: 1 Year | F19: Tự động hóa các task đang làm có khả năng giải quyết task chuyên sâu | H19: 45839 | I19: 149.99 USD/Year | J19: 50% của nội dung - tương ứng 1.894.599 (chưa bao gồm CIT và VAT) | L19: Subcribe Trang Web học các ngôn ngữ lập trình như Python | M19: Nhân viên tự trả tiền trước và claim theo mã dự án training | N19: Biết dùng thành thạo Python và SQL cho công việc | O19: 45444 | P19: Hạng mục cấp thiết - tối đa 17 triệu VND / nội dung | Q19: https://www.w3schools.com/ | R19: Chi tiết nhu cầu của nhân sự đề xuất | S19: Chi tiết đề xuất từ bộ phận Đào tạo (dựa trên chính sách Hỗ trợ chi phí Đào tạo của Công ty) | T19: anhkhoa.nguyen@garena.vn | U19: Đăng ký Hỗ trợ chi phí Đào tạo | V19: 42792 | W19: 45433 | X19: anhkhoa.nguyen@garena.vn | Y19: 45432 | Z19: BP Đào tạo đề xuất | AA19: closed | AB19: Bổ trợ: Bổ trợ cho các kỹ năng và kiến thức trong lĩnh vực chuyên môn của nhân viên | AC19: Loại A: Các khóa học cấp chứng chỉ / Hội thảo / Hội nghị / Văn bằng hoặc Bằng cấp (chỉ dành cho học phần) / Nền tảng khóa học trực tuyến mở ví dụ: Udemy | AD19: FF
A20: TRUE | B20: Em gửi hướng dẫn thanh toán và đăng ký, tham gia khóa học nhé ạ: https://drive.google.com/file/d/18tJB4Rt8SdGgjxlZPYbc5RUclvjFU5EB/view?usp=drive_link | C20: Talentnet | D20: TRUE | E20: 1 ngày | F20: Từ kiến thức của khóa học này có thể tư vấn những trend của thị trường tới business và tìm cách truyền thông/trao đổi về lương thưởng total rewards một cách hiệu quả hơn giúp cải thiện employee engagement và satisfaction về rewards | H20: 45555 | I20: 6 600 000 VND | J20: 100% của nội dung - tương ứng 6 600 000 (chưa bao gồm VAT) | K20: 1 lần | L20: Advanced Total Rewards Strategy | M20: Nhân viên tự trả tiền trước và claim theo mã dự án training | N20: Bổ sung kiến thức về Total Rewards của thị trường để phục vụ công việc phân tích đánh giá lương thưởng và communication một cách hiệu quả về lương thưởng | O20: 45555 | P20: Hạng mục cấp thiết - tối đa 17 triệu VND / nội dung | Q20: https://tln.talentnet.vn/eshop/advanced-total-rewards-strategy | R20: Chi tiết nhu cầu của nhân sự đề xuất | S20: Chi tiết đề xuất từ bộ phận Đào tạo (dựa trên chính sách Hỗ trợ chi phí Đào tạo của Công ty) | T20: vananh.le@garena.vn | U20: Đăng ký Hỗ trợ chi phí Đào tạo | V20: 42801 | W20: 45565 | X20: vananh.le@garena.vn | Y20: 45433 | Z20: BP Đào tạo đề xuất | AA20: processing | AB20: Cấp thiết: Trực tiếp nâng cao kỹ năng và kiến thức trong lĩnh vực chuyên môn của nhân viên | AC20: Loại A: Các khóa học cấp chứng chỉ / Hội thảo / Hội nghị / Văn bằng hoặc Bằng cấp (chỉ dành cho học phần) / Nền tảng khóa học trực tuyến mở ví dụ: Udemy | AD20: HRBP
A21: TRUE | B21: Đăng ký Hỗ trợ chi phí Đào tạo cho 5 thành viên phòng kế toán: 1. Ngô Thị Phương Liên 2. Lê Thị Thanh 3. Nguyễn Thị Thu Trang 4. Nguyễn Thu Trang 5. Trần Thu Trang,,Already got approval from ZY. @HR team, please help to support us. Thanks ,Do sát ngày nên slot cho ngày training gần nhất chỉ còn cho 2 người. Ngoài ra KPMG có tư vấn là khóa học không chuyên sâu, khóa học chỉ mang tính chất giới thiệu, chủ yếu cho người nước ngoài học nên team Finance quyết định không theo khóa học này nữa ạ. | C21: KPMG Việt Nam | D21: TRUE | E21: 3 tháng | F21: 1. Nâng cao chuyên môn nghiệp vụ về kế toán và lập báo cáo tài chính phù hợp với quy định về kế toán 2. Sau khi kết thúc khóa học các thành viên tham dự khóa học sẽ về training lại cho các thành viên trong phòng không tham dự khóa học để bổ sung và nâng cao kiến thức | H21: 45554 | I21: VND 10 625 000 (VND5tr x 5 pax x 50% x 85%) | J21: 100% - tương ứng 10 625 000 | K21: 2 buổi chiều mỗi tháng | L21: Chương trình đào tạo về Tài chính Kế toán năm 2024 tổ chức bởi KPMG | M21: Nhân viên tự trả tiền trước và claim theo mã dự án training | N21: - Bổ sung kiến thức nâng cao nghiệp vụ chuyên môn Tài chính kế toán - Rà soát lại các nghiệp vụ kế toán của công ty để điều chỉnh (nếu có) - Lập báo cáo tài chính năm phù hợp với quy định về kế toán - Hoàn thành khóa học trong 3 tháng ứng dụng nâng cao được vào công việc | O21: 45456 | P21: Hạng mục cấp thiết - tối đa 17 triệu VND / nội dung | Q21: https://29bb37d36e4a4a70a9a35b2b4966a3ce.marketingusercontent.com/m/view/r1lmePK07U4tJGijD3u6j9xP8UBTlFjXqxLckQUwKXIx | R21: Chi tiết nhu cầu của nhân sự đề xuất | S21: Chi tiết đề xuất từ bộ phận Đào tạo (dựa trên chính sách Hỗ trợ chi phí Đào tạo của Công ty) | T21: thutrang.nguyen@garena.vn | U21: Đăng ký Hỗ trợ chi phí Đào tạo | V21: 43172 | W21: 45456 | X21: thutrang.nguyen@garena.vn | Y21: 45450 | Z21: BP Đào tạo đề xuất | AA21: closed | AB21: Cấp thiết: Trực tiếp nâng cao kỹ năng và kiến thức trong lĩnh vực chuyên môn của nhân viên | AC21: Loại A: Các khóa học cấp chứng chỉ / Hội thảo / Hội nghị / Văn bằng hoặc Bằng cấp (chỉ dành cho học phần) / Nền tảng khóa học trực tuyến mở ví dụ: Udemy | AD21: FAC
A22: TRUE | B22: Em gửi hướng dẫn đăng ký học và thanh toán cho anh Thành nhé ạ: https://drive.google.com/file/d/1ujIzkd95wPsCv1yrrm684iP75HJ2s-U-/view?usp=drive_link | C22: TELOS.vn | D22: TRUE | E22: 4 tuần | F22: Figma có những ưu điểm vượt trội photoshop trong việc thiết kế UI. 1. rút ngắn thời gian giao tiếp & tracking khi Nhiều thành viên có thể làm chung trong một project. Requester làm wireframe và designer thiết kế & dev trên cùng 1 giao diện 2. (Chế độ dev mod) Dev có thể copy paste nhanh được mã màu font chữ size chữ khoảng cách lề… - Designer khi làm xong có thể check được luôn CSS trông như nào màu có lệch so với thiết kế không chữ có lệch không... siêu dễ để tự tinh chỉnh lại mà không cần chờ FE dev làm xong mới feedback 3. Plugin - Anima giúp con gà như e có thể export file thiết kế thành CSS trong 5s do máy làm. Dev có thể tận dụng 1 phần code được viết sẵn - Anima có thể export tất cả các file ảnh trong thiết kế thành file png/ jpg dev đỡ phải cắt từng tấm ảnh thủ công - Remove BG giúp tách background nhanh lẹ - Batch Styler giúp tạo style guideline nhanh lẹ có thể thay đổi màu sắc và font chữ hàng loạt thay vì chọn từng layer thủ công | H22: 45499 | I22: 4.400.000 VNĐ (đã bao gồm VAT) | J22: 100% - tương ứng 4.400.000 VNĐ | K22: 2 buổi 1 tuần | L22: Khoá học FIGMA DÀNH CHO DESIGNER/ DEVELOPER | M22: Nhân viên tự trả tiền trước và claim theo mã dự án training | N22: Mục tiêu khoá học: Nắm vững và Sử dụng thành thạo figma Ứng dụng figma vào công việc thiết kế UI ilua và UI cũng như các website của team. | O22: 45474 | P22: Hạng mục cấp thiết - tối đa 17 triệu VND / nội dung | Q22: https://telos.vn/khoa-hoc-thiet-ke-giao-dien-voi-figma/ | R22: Chi tiết nhu cầu của nhân sự đề xuất | S22: Chi tiết đề xuất từ bộ phận Đào tạo (dựa trên chính sách Hỗ trợ chi phí Đào tạo của Công ty) | T22: tienthanh.tran@garena.vn | U22: Đăng ký Hỗ trợ chi phí Đào tạo | V22: 43183 | W22: 45531 | X22: tienthanh.tran@garena.vn | Y22: 45450 | Z22: Nhập sai ngày kết thúc khoá học! | AA22: closed | AB22: Cấp thiết: Trực tiếp nâng cao kỹ năng và kiến thức trong lĩnh vực chuyên môn của nhân viên | AC22: Loại A: Các khóa học cấp chứng chỉ / Hội thảo / Hội nghị / Văn bằng hoặc Bằng cấp (chỉ dành cho học phần) / Nền tảng khóa học trực tuyến mở ví dụ: Udemy | AD22: AOV
A23: TRUE | B23: Em gửi hướng dẫn thanh toán và đăng ký học nhé ạ: https://drive.google.com/file/d/1rJtARzFiuHr0nCGtQjpMR3k9y6gLxu9H/view?usp=drive_link | C23: TELOS.vn | D23: TRUE | E23: 4 tuần | F23: Figma có những ưu điểm vượt trội photoshop trong việc thiết kế UI. 1. Rút ngắn thời gian trao đổi feedback & tracking khi nhiều thành viên có thể làm chung trong một project. Requester làm wireframe và designer thiết kế & dev trên cùng giao diện. 2. (Chế độ dev mod) Dev có thể copy paste nhanh được mã màu font chữ size chữ khoảng cách lề... -Designer khi làm xong có thể check được luôn CSS trông như nào (thông số màu/chữ/bố cục có lệch so với thiết kế không) từ đó trực tiếp chỉnh lại mà không cần phải chờ tới feedback của FE dev sau khi làm xong. 3.Plugin - Anima giúp export file thiết kế thành CSS do máy làm. Dev có thể tận dụng 1 phần code được viết sẵn - Anima có thể export tất cả các file ảnh trong thiết kế thành file png/ jpg dev đỡ phải cắt từng tấm ảnh thủ công - Remove background giúp tách background nhanh lẹ - Batch Styler giúp tạo style guideline nhanh lẹ có thể thay đổi màu sắc và font chữ hàng loạt thay vì chọn từng layer thủ công | H23: 45499 | I23: 4.400.000 VND (đã bao gồm VAT) | J23: 100% - tương ứng 4.400.000 VNĐ | K23: 2 buổi/tuần | L23: Khóa học FIGMA dành cho Designer/Developer | M23: Nhân viên tự trả tiền trước và claim theo mã dự án training | N23: Nắm vững và sử dụng thành thạo figma ứng dụng vào công việc thiết kế UI sự kiện ingame và UI cũng như các website phục vụ cho mục đích truyền thông của team. | O23: 45474 | P23: Hạng mục cấp thiết - tối đa 17 triệu VND / nội dung | Q23: https://telos.vn/khoa-hoc-thiet-ke-giao-dien-voi-figma/ | R23: Chi tiết nhu cầu của nhân sự đề xuất | S23: Chi tiết đề xuất từ bộ phận Đào tạo (dựa trên chính sách Hỗ trợ chi phí Đào tạo của Công ty) | T23: maithanh.le@garena.vn | U23: Đăng ký Hỗ trợ chi phí Đào tạo | V23: 43524 | W23: 45531 | X23: maithanh.le@garena.vn | Y23: 45464 | Z23: BP Đào tạo đề xuất | AA23: closed | AB23: Cấp thiết: Trực tiếp nâng cao kỹ năng và kiến thức trong lĩnh vực chuyên môn của nhân viên | AC23: Loại A: Các khóa học cấp chứng chỉ / Hội thảo / Hội nghị / Văn bằng hoặc Bằng cấp (chỉ dành cho học phần) / Nền tảng khóa học trực tuyến mở ví dụ: Udemy | AD23: AOV
